Workbook

Sheet Title & PRISMA

Sheet Structure of Paper

Sheet Databases & Years
A1: Database Screening (17/4/2026) | B1: # Studies Identified | C1: # Studies Pass Duplicates Discard | D1: # Studies Pass Screening (Stage 1) | E1: # Studies Pass Screening 2 (Stage 2) | F1: # Studies Pass Eligibility Assessment | G1: # Studies Included | H1: Conference | I1: Journal
A2: Web of Science | B2: 282 | C2: 162 | D2: 83 | E2: 83 | F2: 34 | G2: 34 | H2: 11 | I2: 23
A3: Scopus | B3: 443 | C3: 192 | D3: 93 | E3: 93 | F3: 41 | G3: 41 | H3: 26 | I3: 15
A4: IEEE Xplore | B4: 49 | C4: 40 | D4: 38 | E4: 38 | F4: 26 | G4: 26 | H4: 9 | I4: 17
A5: ScienceDirect | B5: 18 | C5: 18 | D5: 18 | E5: 18 | F5: 15 | G5: 15 | H5: 0 | I5: 15
A6: ACM DL | B6: 52 | C6: 51 | D6: 6 | E6: 2 | F6: 2 | G6: 2 | H6: 1 | I6: 1
A7: Total | B7: =SUM(B2:B6) -> 844 | C7: =SUM(C2:C6) -> 463 | D7: =SUM(D2:D6) -> 238 | E7: =SUM(E2:E6) -> 234 | F7: =SUM(F2:F6) -> 118 | G7: =SUM(G2:G6) -> 118 | H7: =SUM(H2:H6) -> 47 | I7: =SUM(I2:I6) -> 71
A11: Database
A12: Web of Science | B12: 0.2881 | C12: Conference | D12: 11
C13: Journal | D13: 23
A14: Scopus | B14: 0.3475 | C14: Conference | D14: 26
C15: Journal | D15: 15
A16: IEEE Xplore | B16: 0.2203 | C16: Conference | D16: 9
C17: Journal | D17: 17
A18: Science Direct | B18: 0.1271 | C18: Conference | D18: 0
C19: Journal | D19: 15
A20: ACM DL | B20: 0.017 | C20: Conference | D20: 1
C21: Journal | D21: 1
A35: Quality Score | B35: Number of Publication
A36: 1 | B36: 0
A37: 1.25 | B37: 1
A38: 1.5 | B38: 0
A39: 1.75 | B39: 4
A40: 2 | B40: 5
A41: 2.25 | B41: 6
A42: 2.5 | B42: 14
A43: 2.75 | B43: 12
A44: 3 | B44: 7
A45: 3.25 | B45: 16
A46: 3.5 | B46: 21
A47: 3.75 | B47: 30
... A52: 5 | B52: 5
A57: Publication trends
A58: Year | B58: Included
A59: 2022 | B59: 1
A60: 2023 | B60: 4
A61: 2024 | B61: 29
A62: 2025 | B62: 61
A63: 2026 | B63: 23
A65: Year | B65: Google Scholar
...

Sheet Master Table Description
A1: Column | B1: Field Name | C1: Description / What to Extract
A2: A | B2: Paper ID | C2: Unique identifier for each paper, e.g., P001, P002, P003.
A3: B | B3: Full Citation | C3: Complete citation including authors, year, title, venue, volume/issue, pages, and article number where available.
A4: C | B4: Title | C4: Paper title
A5: D | B5: University | C5: Institution
A6: E | B6: Country | C6: Country
A7: F | B7: Publication Year | C7: Year the paper was published, accepted, or made available online.
A8: G | B8: Publication Venue | C8: Name of the journal, conference, workshop, book series, or preprint server.
A9: H | B9: Publisher | C9: Publishing body, e.g., IEEE, Elsevier, Springer, ACM, Frontiers, MDPI, AAAI, IJCAI, arXiv.
A10: I | B10: DOI / URL | C10: DOI, official publisher link, arXiv link, or stable URL.
A11: J | B11: Publication Type | C11: Journal article, conference paper, workshop paper, review paper, book chapter, or preprint.
A12: K | B12: Database Source | C12: Source from which the paper was retrieved (Scopus, Web of Science, IEEE Xplore, ACM DL, ScienceDirect, SpringerLink)
... A61: BH | B61: RQ Mapping | C61: Map the paper to your RQs using: Primary: RQx; Secondary: RQx, RQx.

Sheet Master Table
A1: Paper ID | B1: Full Citation | C1: Title | D1: University | E1: Country | F1: Publication Year | G1: Publication Venue | H1: Publisher | I1: DOI / URL | J1: Publication Type | K1: Database Source | L1: Paper Category | M1: E&QA Score | N1: Application Domain | O1: Specific Task | P1: Data Modality | Q1: Signal Dimensionality | R1: Signal Characteristics | S1: Dataset Name | T1: Dataset Type | U1: Dataset Size | V1: Dataset Balance / Split | W1: Hybrid Topology | X1: SNN Component | Y1: Neuron Model | Z1: Transformer Component | AA1: Attention Type | AB1: SNN–Transformer Interface Mechanism | AC1: Model Depth / Scale | AD1: Parameter Count | AE1: Design / Contribution Type | AF1: Input Encoding Method | AG1: Encoding Parameters | AH1: Encoding Learned or Fixed | AI1: Event / Spike Representation | AJ1: Temporal Resolution | AK1: Output Decoding Method | AL1: Encoding / Temporal Information Analysis | AM1: Training Paradigm | AN1: Training Method | AO1: Surrogate Gradient Function | AP1: ANN-to-SNN Conversion Method | AQ1: Optimizer | AR1: Loss Function | AS1: Training Hyperparameters | AT1: Primary Performance Metric | AU1: Primary Metric Value | AV1: Secondary Metrics | AW1: Baseline Models Compared | AX1: Performance Gain Over Baseline | AY1: Statistical Validation | AZ1: Ablation Study | BA1: Training Framework / Code Availability | BB1: Target Hardware | BC1: Hardware Deployment Status | BD1: Energy Evidence | BE1: Latency / Memory / Complexity Evidence | BF1: Comparison with ANN Baseline | BG1: Main Contribution / Key Limitation | BH1: RQ Mapping
A2: P001 | B2: Xu, B., Yin, Y., Iyer, V., & Li, P. (2025). Bishop: Sparsified Bundling Spiking Transformers on Heterogeneous Cores with Error-constrained Pruning. In Proceedings of the 52nd Annual International Symposium on Computer Architecture (ISCA ’25), June 21–25, 2025, Tokyo, Japan. ACM, New York, NY, USA, 14 pages. https://doi.org/10.1145/3695053.3731063 | C2: Bishop: Sparsified Bundling Spiking Transformers on Heterogeneous Cores with Error-constrained Pruning | D2: University of California | E2: United States | F2: 2025 | G2: Proceedings of the 52nd Annual International Symposium on Computer Architecture, ISCA ’25 | H2: ACM | I2: https://doi.org/10.1145/3695053.3731063 | J2: Conference paper | K2: ACM Digital Library | L2: Hardware-focused | M2: 4.5 | N2: Neuromorphic Hardware and Edge AI Acceleration | O2: Efficient inference acceleration for spiking Transformer workloads on image, event-based gesture, and speech-command recognition benchmarks | P2: Static images, event-camera/DVS data, and speech-command data | Q2: 2D image/token sequences; 2D spatiotemporal event data; sequence-based speech-command tokens | R2: CIFAR images are 32 × 32 and split into 64 tokens; ImageNet-100 images are 224 × 224 and split into 196 tokens; DVS-Gesture input is 128 × 128 and split into 64 tokens; models use 4–20 timesteps depending on dataset | S2: CIFAR10, CIFAR100, ImageNet-100, DVS-Gesture-128, Google Speech Command V2 | T2: Public benchmark datasets | U2: NR | V2: NR | W2: Spiking Transformer workload accelerated through a dedicated HW/SW co-design framework; model uses spiking tokenizer, multi-head spiking self-attention, spiking MLP blocks, and LIF-based spike processing | X2: LIF neurons, spiking tokenizer, spiking MLP, spiking Q/K/V projections, spike generator, binary spike activations | Y2: LIF | Z2: Multi-head Spiking Self-Attention block, residual encoder blocks, Q/K/V/O projection layers, spiking MLP block | AA2: Multi-head spiking self-attention; binary Q/K/V attention; softmax-free spiking attention | AB2: Spiking tokenizer converts input into T × N × D spiking token representation; LIF layers generate spike-form Q/K/V; Token-Time Bundle represents spiking tokens across time for hardware processing | AC2: Model 1: CIFAR10, 4 blocks, T=10, N=64, D=384; Model 2: CIFAR100, 4 blocks, T=8, N=64, D=384; Model 3: ImageNet-100, 8 blocks, T=4, N=196, D=128; Model 4: DVS-Gesture, 2 blocks, T=20, N=64, D=128; Model 5: Google SC, 4 blocks, T=8, N=256, D=384 | AD2: NR | AE2: New accelerator architecture and HW/SW co-design framework; Token-Time Bundle representation; heterogeneous dense/sparse/attention cores; Bundle-Sparsity Aware training; Error-Constrained TTB Pruning | AF2: Spiking tokenizer / token-based spiking representation; exact spike encoding rule for each dataset is NR | AG2: Timesteps: 4–20 depending on dataset; token counts: 64, 196, or 256; feature dimensions: 128 or 384; TTB bundle parameters BSt and BSn explored | AH2: NR | AI2: Binary spike tensor; spiking activations arranged as Token-Time Bundles; binary spiking Q/K/V; active and inactive TTBs | AJ2: 4 timesteps for ImageNet-100, 8 for CIFAR100 and Google Speech Command, 10 for CIFAR10, 20 for DVS-Gesture | AK2: Global average pooling across tokens and time followed by a linear prediction layer; hardware spike generator produces binary spike outputs | AL2: Yes. The paper analyzes spatiotemporal sparsity, Token-Time Bundle sparsity, active/inactive bundle distribution, bundle size sensitivity, and pruning effects on attention computation | AM2: Supervised learning for benchmark classification models; HW/SW co-design training pipeline | AN2: Bundle-Sparsity Aware training and ECP-aware training; loss combines cross-entropy with bundle-level sparsity loss | AO2: NR | AP2: N/A | AQ2: NR | AR2: Cross-entropy loss plus bundle-level sparsity regularization: Ltot = LCE + λLbsp | AS2: Batch size 256 and 300 epochs for CIFAR and ImageNet-100; batch size 64 and 100 epochs for DVS-Gesture; λ = 1 for CIFAR10, 0.5 for CIFAR100, 0.3 for ImageNet, 1.0 for DVS-Gesture; ECP pruning threshold 10 for DVS-Gesture and 6 for other models | AT2: Latency speedup and energy efficiency improvement | AU2: Average 5.91× speedup and 6.11× energy-efficiency improvement over PTB SNN accelerator; 299× average speedup over NVIDIA Jetson Nano edge GPU | AV2: Accuracy, chip area, power, latency, energy dissipation, EDP, pruning ratio, memory access reduction, attention-layer speedup | AW2: NVIDIA Jetson Nano edge GPU; Parallel Time Batching SNN accelerator; PTB; comparison also includes ANN and SNN accuracy references in background | AX2: Bishop+BSA+ECP achieves up to 7.73× speedup over PTB on ImageNet-100 and 4.06× on DVS-Gesture; attention core reduces latency by 10.7–23.3× and gives 1.39–1.96× energy saving over PTB | AY2: Benchmark-based evaluation and cycle-accurate hardware simulation; no repeated runs, standard deviation, confidence interval, or significance test reported | AZ2: Full. Includes BSA effect, ECP threshold analysis, stratification strategy, TTB bundle volume sensitivity, hardware area/power breakdown, and latency/energy comparisons | BA2: PyTorch-based training flow; CACTI 7.0 for memory energy estimation; STONNE simulator for sparse core simulation; code availability NR | BB2: Dedicated heterogeneous ASIC-style accelerator; 28 nm CMOS synthesis; dense core, sparse core, attention core, spike generator, GLB/DRAM memory hierarchy | BC2: RTL synthesis and cycle-accurate simulation; no fabricated chip or real neuromorphic hardware deployment reported | BD2: Estimated energy using CACTI 7.0, DRAM power model, RTL synthesis, and cycle-accurate accelerator simulation; not measured from fabricated silicon | BE2: Reports 2.96 mm² die area, 627 mW peak power, 500 MHz clock; 144 KB weight GLB; two 12 KB spike TTB GLBs; reports latency, energy, EDP, memory access, and attention computation reduction | BF2: Yes. Uses NVIDIA Jetson Nano edge GPU as an ANN hardware baseline and includes ANN/SNN accuracy comparison table, but the main efficiency comparison is against PTB SNN accelerator | BG2: Contribution: first dedicated hardware accelerator and HW/SW co-design framework for spiking Transformers using Token-Time Bundles, heterogeneous cores, BSA training, and ECP pruning. Limitation: evaluation is based on simulation and RTL synthesis, not fabricated hardware; dataset focus is mainly classification benchmarks | BH2: Primary: RQ5; Secondary: RQ2, RQ3, RQ4
A3: P002 | B3: Zhou, Y., Yin, H., Tan, C., Wu, Q., Sun, C., & Hong, R. (2026). An Efficient Hybrid Cascade Tracker with Spiking Neural Networks for Event Domain Tracking. ACM Transactions on Multimedia Computing, Communications, and Applications, 22(3), Article 75, 20 pages. https://doi.org/10.1145/3795518 | C3: An Efficient Hybrid Cascade Tracker with Spiking Neural Networks for Event Domain Tracking | D3: Anhui University | E3: China | F3: 2026 | G3: ACM Transactions on Multimedia Computing, Communications, and Applications | H3: ACM | I3: https://doi.org/10.1145/3795518 | J3: Journal article | K3: ACM Digital Library | L3: Application-focused | M3: 4.5 | N3: Event-Based / Neuromorphic Vision | O3: Single object tracking / bounding-box prediction in event streams | P3: Event-camera data; simulated event data from RGB frame datasets | Q3: 2D spatiotemporal event representation; event voxel/grid-style frame representation | R3: Event stream represented as quadruples (x, y, t, p) with spatial location, timestamp, and polarity; events between adjacent frames are aggregated into an n-bin voxel grid with positive and negative polarity frames | S3: VisEvent, FE108, COESOT, Event-OTB, Event-VOT | T3: Public event-based tracking benchmarks; simulated event datasets converted from RGB tracking benchmarks | U3: VisEvent: 820 videos / 371,127 frames; FE108: 108 videos / 208,672 frames; COESOT: 1,354 videos / 478,721 frames; OTB100/Event-OTB: 100 videos / 59,040 frames; VOT2019/Event-VOT: 60 videos / 19,935 frames | V3: Uses public benchmark training/testing protocols; exact class/object balance NR | W3: Parallel/cascade hybrid CNN–SNN–Transformer topology; EHCT uses repeated HCST blocks containing C-SNN and T-SNN branches, connected by a T2C Adapter and fused by CTFM | X3: C-SNN branch, T-SNN branch, LIF layers, spike-based self-attention, spike-based MLP, spike-driven temporal encoding | Y3: LIF | Z3: Transformer-SNN encoder block; spike-based self-attention; spike-based MLP; T-SNN branch | AA3: Spike-based self-attention; scaled dot-product attention in CTFM fusion module | AB3: Q and K are projected then converted into spike sequences using LIF neurons; spike-form Q and K allow dot-product computation through logical AND and summation; T2C Adapter concatenates T-SNN and C-SNN outputs, applies 1 × 1 convolution, then LIF for spike-form compatibility | AC3: HCST block number N tested from 1 to 5; final model uses N = 3 HCST blocks; T-SNN can be stacked by N layers | AD3: NR | AE3: New event-domain hybrid cascade tracker; HCST block; C-SNN and T-SNN dual-branch design; T2C Adapter; CTFM fusion module | AF3: Event-to-frame / voxel-grid representation; events between adjacent frames are aggregated into n bins and separated into positive and negative polarity frames | AG3: Event tuple (x, y, t, p); n-bin voxel grid; positive and negative event frames; timestep T = 5 for SNN energy analysis; LIF threshold h = 1.0; leakage factor uses τ = 2.0 | AH3: Fixed event representation; feature fusion and projection layers are learned | AI3: Event frames, positive/negative polarity frames, spike sequences, spike-form Q and K, LIF spike activations | AJ3: Event cameras provide microsecond-level temporal resolution; SNN timestep T = 5 in energy analysis | AK3: Classifier and regressor heads produce the tracking bounding box | AL3: Partial. The paper analyzes event sparsity, firing rate of LIF layers, spike-driven temporal encoding, and feature visualizations, but does not deeply quantify temporal information loss | AM3: Supervised learning within Siamese tracking framework | AN3: Surrogate-gradient direct training using SpikeJelly; SiamFC++/STNet-style tracking loss framework | AO3: ATan surrogate gradient | AP3: N/A | AQ3: Stochastic Gradient Descent | AR3: Follows SiamFC++ and STNet tracking loss; exact full loss formula NR | AS3: Batch size 32; trained on NVIDIA RTX 3090 GPUs; backbone frozen in first epoch; backbone learning rate 0.1 from epoch 2; other components use learning rate 0.001 to 0.01 during epochs 1–5 then decay 10× every 5 epochs; SGD momentum 0.9; weight decay 5e-5; LIF threshold h = 1.0; τ = 2.0 | AT3: Success Rate, Precision Rate, Overlap Precision | AU3: VisEvent: SR 39.6, OP0.50 46.5, OP0.75 25.6, PR 55.5; FE108: SR 54.5, OP0.50 69.0, OP0.75 22.9, PR 85.1; COESOT: SR 45.1, OP0.50 53.9, OP0.75 27.2, PR 52.2 | AV3: Normalized Precision Rate, FPS, firing rate, theoretical energy consumption | AW3: ATOM, DiMP, PrDiMP, TransT, ToMP, STARK, MixFormer, MDNet, CEUTrack, HDETrack, FENet, STNet, DANet, AFNet, HiT, FERMT | AX3: On VisEvent, EHCT achieves best PR 55.5 and OP0.50 46.5; on FE108, EHCT achieves best SR 54.5 and PR 85.1; on Event-OTB and Event-VOT, EHCT outperforms CEUTrack, STNet, AFNet, and HDETrack in SR and PR | AY3: Public benchmark evaluation and ablation experiments; no standard deviation, confidence interval, repeated-run analysis, or significance test reported | AZ3: Full. Includes C-SNN vs T-SNN branches, with/without SNN, T2C Adapter variants, CTFM variants, number of HCST blocks, lightweight backbone, and single-block variants | BA3: PyTorch; SpikingJelly; source code stated to be available at GitHub: masac11/EHCT | BB3: GPU/CPU for implementation; future neuromorphic hardware and embedded platforms mentioned | BC3: Evaluated on PC/GPU; no real neuromorphic hardware deployment reported | BD3: Theoretical energy estimate using SOP, firing rate, timestep, FLOPs, MAC energy 4.6 pJ, and AC energy 0.9 pJ; average firing rate about 2.1567%; claims approximately 45× energy efficiency over ANN with same structure | BE3: EHCT runs at 95 FPS on VisEvent; inference requires 2 GB GPU memory and 5 GB CPU RAM; lightweight variants report up to 111 FPS but lower accuracy | BF3: Yes. Compares with RGB/ANN-based trackers such as ATOM, DiMP, PrDiMP, TransT, ToMP, STARK, MixFormer, MDNet, HiT, and FERMT | BG3: Contribution: proposes EHCT, a hybrid CNN–SNN–Transformer tracker for event-domain object tracking, using HCST blocks, T2C Adapter, and CTFM fusion to combine local spike features and global Transformer context. Limitation: struggles under extreme fast motion and long occlusion; energy evidence is theoretical and no real neuromorphic deployment is reported | BH3: Primary: RQ1; Secondary: RQ2, RQ3, RQ4, RQ5
A4: P003 | B4: Alohali, M. A., Saleem, N., Rhouma, D., Medani, M., Elmannai, H., & Bourouis, S. (2024). Temporally Dynamic Spiking Transformer Network for Speech Enhancement. IEEE Access, 12, 146513–146526. https://doi.org/10.1109/ACCESS.2024.3444596 | C4: Temporally Dynamic Spiking Transformer Network for Speech Enhancement | D4: Princess Nourah Bint Abdulrahman University | E4: Saudi Arabia | F4: 2024 | G4: IEEE Access | H4: IEEE | I4: https://doi.org/10.1109/ACCESS.2024.3444596 | J4: Journal article | K4: IEEE Xplore | L4: Application-focused | M4: 4 | N4: Speech, Audio, and Auditory Processing | O4: Single-channel speech enhancement / noisy speech reconstruction | P4: Audio signal represented as complex spectrogram | Q4: 1D temporal speech waveform converted to 2D time-frequency spectrogram | R4: Input is real and imaginary parts of noisy spectrogram, Y ∈ R(2×T×F); sampling rate 16 kHz; STFT window length 512 samples; frame shift 16 ms | S4: WSJ0-SI84; VCTK+DEMAND | T4: Public benchmark speech enhancement datasets | U4: WSJ0-SI84: 3000 training utterances, 1000 test utterances, approximately 150 hours of training mixtures; VCTK+DEMAND: 11,572 training mixtures and 824 test mixtures | V4: WSJ0-SI84: training utterances from 83 speakers, testing from unseen speakers; SNR −5 dB to 5 dB for training and −3, 0, 3, 6 dB for testing. VCTK+DEMAND: 28 training speakers, 2 test speakers; training SNRs 0, 5, 10, 15 dB; testing SNRs 2.5, 7.5, 12.5, 17.5 dB | W4: CNN encoder-decoder with a dual-branch Spiking Transformer Network bottleneck | X4: Spike neuron layers, spike-based Q/K/V, spiking self-attention, spiking Transformer encoder | Y4: NR | Z4: Spiking Transformer Network bottleneck, spiking self-attention, MLP block, temporal attention branch, frequency attention branch | AA4: Spiking self-attention; temporal attention; frequency attention | AB4: Q, K, and V are first generated using learnable matrices and batch normalization, then transformed into spike sequences through spike neuron layers; spike-based Q/K/V are used in the self-attention computation | AC4: Encoder has four convolutional layers with multi-scale feature blocks; decoder mirrors encoder with four sub-pixel deconvolutional layers; bottleneck uses dual-branch STN | AD4: 3.14 million parameters | AE4: New application architecture combining convolutional encoder-decoder, multi-scale feature extraction, and dual-branch Spiking Transformer bottleneck for speech enhancement | AF4: Complex spectrogram input; real and imaginary parts of noisy speech spectrogram are processed by CNN encoder, then STN converts projected features into spike-based Q/K/V | AG4: Sampling rate 16 kHz; window length 512 samples; frame shift 16 ms; spike Q/K/V generated through spike neuron layers; α and β adaptive branch weights initialized as 1 | AH4: Partially learned: spectrogram extraction is fixed, while Q/K/V projections and branch weights are learned | AI4: Spike sequences for Q, K, and V; spike-based attention representations with binary 0/1 spike values | AJ4: Frame shift 16 ms; temporal frames T in spectrogram; exact SNN timestep NR | AK4: Decoder outputs real and imaginary components of the estimated clean spectrum, followed by inverse STFT to reconstruct waveform | AL4: Partial. The paper discusses temporal/spectral dependency modeling and visualizes spectrogram quality, but does not deeply analyze spike encoding information loss or spike temporal preservation | AM4: Supervised learning | AN4: Direct end-to-end training of CNN encoder-decoder with Spiking Transformer bottleneck | AO4: NR | AP4: N/A | AQ4: Adam | AR4: Weighted spectro-temporal loss: L = υLtime + (1−υ)Lfrequency, with υ = 0.4 | AS4: Batch size 16; 100 epochs; Adam with α = 0.001, β1 = 0.9, β2 = 0.999, ε = 10⁻⁸; learning rate starts at 0.001 and decays to 0.0005, 0.0002, and 0.0001; dropout 0.20 | AT4: PESQ, ESTOI, SI-SDR | AU4: WSJ0-SI84 seen condition average: ΔSI-SDR = 11.52 dB, ΔESTOI = 39.67%, ΔPESQ = 1.22. VCTK+DEMAND: STOI = 95.0, PESQ = 3.13, SNRSeg = 11.12 | AV4: STOI, SNRSeg, FW-SNRSeg, Csig, Cbak, Covl, MACs, RTF, memory footprint | AW4: CRN, DPRNN, GCRN, DCCRN, AECNN, CTSNet, GaGNet, CPBNet, PHASEN, RDLNet, DEMUCS, TSTNN, MSSA-TCN, FAFNet, PFRNet, UTFAT, DBS4D, DBCRN, SADN-UNet, NSNet, DPT-FSNet, DPTGAN, DPT-ECA, FullSubNet+, FRCRN, DF-Net | AX4: On WSJ0-SI84, TD-STNet outperforms CRN by 3.83 dB ΔSI-SDR, 7.28% ΔESTOI, and 0.35 ΔPESQ. On VCTK+DEMAND, it improves over several baselines while keeping 3.14M parameters and 0.18 RTF | AY4: Benchmark evaluation on seen/unseen speakers and noises; no standard deviation, confidence interval, repeated-run analysis, or statistical significance test reported | AZ4: Full. Includes TD-STNet with traditional Transformer, without STN bottleneck, STN with only FAB, STN with only TAB, and full dual-branch STN | BA4: Framework NR; code availability NR | BB4: CPU/GPU evaluation; real-time speech enhancement setting | BC4: Evaluated computationally on CPU/GPU; no neuromorphic hardware deployment reported | BD4: No direct energy measurement; efficiency discussed through parameters, MACs, real-time factor, inference time, and memory footprint | BE4: 3.14M parameters; 9.64 G/s MACs; 0.18 RTF; approximately 10.12 MB memory; CPU processing time 0.20 s; PMFP 0.28 G; BMFP 0.29 G; training batch time 0.25 s | BF4: Yes. Compares against many ANN/CNN/RNN/Transformer-based speech enhancement baselines | BG4: Contribution: proposes TD-STNet, a convolutional encoder-decoder with dual-branch Spiking Transformer bottleneck for temporal and spectral speech enhancement. Limitation: attention only uses current input at each time step, underusing historical temporal information; no real neuromorphic hardware or measured energy evaluation | BH4: Primary: RQ1; Secondary: RQ2, RQ3, RQ4, RQ5
A5: P004 | B5: Fang, C., Shen, Z., Li, T., Zhao, S., Tian, F., Yang, J., & Sawan, M. (2025). A 28nm Spiking Vision Transformer Accelerator with Dual-Path Sparse Compute Core and EMA-free Self-Attention Engine for Embodied Intelligence. IEEE Transactions on Circuits and Systems for Artificial Intelligence. https://doi.org/10.1109/TCASAI.2025.3596210 | C5: A 28nm Spiking Vision Transformer Accelerator with Dual-Path Sparse Compute Core and EMA-free Self-Attention Engine for Embodied Intelligence | D5: Westlake University | E5: China | F5: 2025 | G5: IEEE Transactions on Circuits and Systems for Artificial Intelligence | H5: IEEE | I5: https://doi.org/10.1109/TCASAI.2025.3596210 | J5: Journal article | K5: IEEE Xplore | L5: Hardware-focused | M5: 4.5 | N5: Robotics, Autonomous Systems, and UAV Vision | O5: Real-time visual cortex acceleration for embodied intelligence tasks, including manipulation and navigation | P5: RGB image frames encoded into spike format | Q5: 2D image sequence / spatiotemporal visual input | R5: Uses three consecutive visual frames per inference; input resolutions include 256 × 256 and 128 × 128; RGB input is encoded into spike format with 8 timesteps | S5: CortexBench tasks; Adroit; MetaWorld; DeepMind Control; ObjectNav; ImageNav; HM3DSem; Gibson; Mujoco-based datasets | T5: Public embodied AI / robotic manipulation / navigation benchmark datasets | U5: NR | V5: NR | W5: Spiking Vision Transformer visual cortex accelerator; spiking tokenizer/encoder converts RGB input to spike format, followed by spiking Transformer blocks and an off-chip non-spiking policy MLP | X5: Spike encoder layer, spike-format feature maps, spiking Transformer blocks, spike-based Q/K/V, 1-bit spike activations | Y5: Spiking neurons used for input encoding; exact neuron model NR | Z5: Spiking Vision Transformer; spiking Transformer blocks; Spiking Self-Attention; ViT-B and ViT-L visual cortex models | AA5: Spiking self-attention; linear attention; softmax-free SSA | AB5: RGB frames are encoded into spike format with 8 timesteps; patch embeddings are processed by spiking Transformer blocks; Q, K, and V are represented as 1-bit spike matrices in SSA | AC5: ViT-B and ViT-L are mapped; typical target SSA setting uses N = 256 and head dimension d = 64; ideal hardware efficiency supports N ≤ 4096 and D ≤ 4096 | AD5: ViT-B: 86M parameters; ViT-L: 307M parameters | AE5: Fabricated 28nm Spiking Vision Transformer accelerator; dual-path sparse compute core; group-wise frame-differential dataflow; EMA-free SSA engine; first-order SSA approximation; KV-first dataflow; transpose engine; unified 1b/8b adder-tree array | AF5: RGB-to-spike encoding using an encoder layer with spiking neurons; group-wise frame-differential dataflow uses 1 raw frame and 2 differential frames | AG5: Spike timestep = 8; input group size = 3 frames; block-wise CSR compression for differential frames; 1-bit spike representation; INT8 precision for weights/operations | AH5: Partially learned: spike encoder layer is part of the model, while frame-differential dataflow and block-wise CSR compression are hardware/dataflow mechanisms | AI5: 1-bit spike feature maps; raw bitmaps for raw frames; block-wise CSR format for differential sparse frames; spike-based Q/K/V matrices | AJ5: 8 SNN timesteps; 3-frame temporal window for embodied intelligence inference | AK5: CLS tokens from three frame embeddings are extracted and concatenated, then passed to a 3-layer non-spiking policy MLP to generate the agent action | AL5: Yes. The paper analyzes input sparsity, frame-to-frame similarity, frame-differential sparsity, cosine similarity between approximated and exact SSA, and energy efficiency under different sparsity levels | AM5: Pretrained visual representation / embodied AI inference setting; exact SNN training paradigm NR | AN5: NR | AO5: NR | AP5: NR | AQ5: NR | AR5: NR | AS5: NR | AT5: Energy efficiency; energy per inference/frame; task latency; accuracy loss compared with INT8 ViT | AU5: Energy efficiency: 57.7 TOPS/W for manipulation, 51.7 TOPS/W for ObjectNav, 41.2 TOPS/W for ImageNav; energy per inference: 1.79 mJ for ViT-B and 3.78 mJ for ViT-L | AV5: FPS, EMA reduction, accuracy loss, sparsity, power, voltage/frequency scaling, die area, SRAM size, latency | AW5: Vanilla INT8 ViT models; SOTA ViT accelerators including VLSI’23, ISSCC’22, ISSCC’23, JSSC’24, and VLSI’24 processors | AX5: 58% input EMA reduction; 83.6% lower SSA memory space; 46.5% lower SSA computation latency; 4× faster 1-bit matrix multiplication with 19% area overhead; 4.1× lower energy than previous work with same model; 34.8% higher task-level energy efficiency than SOTA ViT accelerator | AY5: Hardware measurement across multiple EAI tasks; no standard deviation, confidence interval, or significance test reported | AZ5: Partial/full hardware ablation. Reports system-level performance with optimizations enabled/disabled, SSA approximation accuracy loss, cosine similarity analysis, sparsity-energy analysis, and area/power breakdown | BA5: Hardware implemented in 28nm CMOS; FPGA-based testing platform; code availability NR | BB5: Fabricated 28nm CMOS accelerator chip; FPGA-based test platform; RISC-V controller; 32 compute cores; 640KB SRAM | BC5: Fabricated and measured silicon chip; validated on real hardware test platform for EAI tasks | BD5: Measured chip power and energy using an independent power supply / Keysight B2902A DC power analyzer; reports energy per frame and TOPS/W including EMA | BE5: Die area 6.5 mm²; 640KB SRAM; 0.55–1.1V; 30–200 MHz; power 9.04–222.65 mW; task latency 29.76 ms for ViT-B and 62.77 ms for ViT-L; FPS 33.60, 15.93, and 81.43 across tasks | BF5: Yes. Compares accuracy loss against INT8 vanilla ViT and compares hardware efficiency against non-spiking ViT accelerators | BG5: Contribution: proposes and fabricates a 28nm Spiking Vision Transformer accelerator for embodied intelligence with dual-path sparse computation, EMA-free SSA, and unified 1b/8b adder-tree acceleration. Limitation: policy MLP remains off-chip on FPGA; evaluation focuses on embodied vision tasks rather than broader SNN–Transformer domains; training details are not reported | BH5: Primary: RQ5; Secondary: RQ2, RQ3
A6: P005 | B6: Fang, C., Shen, Z., Wang, Z., Wang, C., Zhao, S., Tian, F., Yang, J., & Sawan, M. (2025). An Energy-Efficient Unstructured Sparsity-Aware Deep SNN Accelerator With 3-D Computation Array. IEEE Journal of Solid-State Circuits, 60(3), 977–989. https://doi.org/10.1109/JSSC.2024.3507095 | C6: An Energy-Efficient Unstructured Sparsity-Aware Deep SNN Accelerator With 3-D Computation Array | D6: Westlake University | E6: China | F6: 2025 | G6: IEEE Journal of Solid-State Circuits | H6: IEEE | I6: https://doi.org/10.1109/JSSC.2024.3507095 | J6: Journal article | K6: IEEE Xplore | L6: Hardware-focused | M6: 4.5 | N6: Event-Based / Neuromorphic Vision | O6: Hardware acceleration of direct-trained deep SNNs, including Spikingformer and Spiking ResNet, for image classification and gesture recognition | P6: Static image data and dynamic vision sensor/event data | Q6: 2D image inputs converted to spike sequences; event/spike sequences with temporal timesteps | R6: Static images are encoded into spike format using one convolution layer and spiking neuron layer; DVS raw spike sequences are segmented into T = 8 timesteps and accumulated before re-encoding into spike format | S6: ImageNet, CIFAR-10, DVS-128 Gesture | T6: Public static image classification and dynamic vision/event-based gesture recognition benchmarks | U6: NR | V6: NR | W6: Spiking Transformer and Spiking ResNet workloads mapped to a fabricated sparse DSNN accelerator; Spiking Transformer uses spiking tokenizer, spiking Q/K/V generation, and spiking self-attention | X6: Spiking tokenizer, LIF neurons, spike-only operators, spiking convolution, spiking Q/K/V generation, spiking self-attention, single-bit spikes | Y6: LIF | Z6: Spiking Transformer / Spikingformer blocks; spiking tokenizer; S_QKV_Gen; spiking self-attention | AA6: Spiking self-attention; softmax-free spike attention | AB6: LIF neurons are placed before operators so that SCONV, linear layers, and attention receive 1-bit spike inputs; S_QKV_Gen converts input sequence X ∈ R(T×N×Dx) into spike-form Q, K, and V | AC6: Spikingformer-8-768: 8 Transformer blocks, hidden dimension 768; Spiking ResNet-9-32: 9 residual layers, 32 channels; timestep T = 8 | AD6: NR | AE6: Fabricated sparse DSNN accelerator with 3-D computation array, unstructured non-zero data fetcher, two-stage fan-in prioritized sparse dataflow, and multimode unified computation scheduler for SCONV, S_QKV_Gen, and SSA | AF6: Static images encoded into spike format by a convolution layer and spiking neuron layer; DVS event data segmented into T = 8 timesteps and accumulated, then encoded again using an additional convolution layer | AG6: Timestep T = 8; 8-bit weights; single-bit spike activations; two-stage bitmap format using global bitmap and local bitmap | AH6: Partially learned: the convolutional spike encoder is model-based, while two-stage bitmap compression and sparse scheduling are fixed hardware/dataflow mechanisms | AI6: Single-bit spike sequences; global bitmap for positions where all T spikes are zero/non-zero; local bitmap for timestep-level spike information; compressed spike bitmap format | AJ6: 8 timesteps for evaluated models | AK6: Classification output from mapped Spikingformer / Spiking ResNet models; exact classifier decoding details NR | AL6: Yes. The paper analyzes timestep-parallel processing, spike sparsity, per-layer sparsity, two-stage bitmap storage efficiency, and energy efficiency under different spike sparsity levels | AM6: Direct-trained SNN inference workloads; hardware paper does not train models directly | AN6: NR | AO6: NR | AP6: N/A for the evaluated direct-trained SNN setting | AQ6: NR | AR6: NR | AS6: NR | AT6: Energy efficiency; energy per spike operation; recognition accuracy | AU6: Best energy efficiency: 0.078 pJ/SOP; ImageNet accuracy using Spikingformer: 77.6% / 77.7%; ImageNet energy efficiency: 42.8 TOPS/W | AV6: TOPS/W, pJ/SOP, task energy, latency, peak performance, area efficiency, power, voltage/frequency scaling, spike sparsity, storage efficiency | AW6: SOTA SNN processors, sparse ANN processors, Spikingformer, Spiking ResNet, prior ISSCC/JSSC accelerators | AX6: 68.3% external memory access reduction from timestep-parallel dataflow; 78% SSA operation reduction using sparse attention skipper; 51.1% SCONV latency reduction from memory router; 1.75× higher ImageNet energy efficiency than SOTA SNN processors; 1.4× higher than sparse ANN processors | AY6: Hardware measurement and benchmark comparison; no standard deviation, confidence interval, or statistical significance testing reported | AZ6: Partial hardware ablation/analysis. Includes energy efficiency vs spike sparsity, storage efficiency comparison, load-balancer window-size analysis, per-layer energy/sparsity analysis, and operator-specific scheduling analysis | BA6: Fabricated 40-nm CMOS accelerator; FPGA-based testing platform; software/code availability NR | BB6: Fabricated 40-nm CMOS neuromorphic accelerator with 3 computation clusters, 9 sparse cores, 3-D computation arrays, FPGA test platform | BC6: Fabricated and measured silicon chip | BD6: Measured chip power using Keysight B2902A DC power analyzer; reports TOPS/W, pJ/SOP, task energy, and voltage/frequency scaling | BE6: Die area 1.54 × 1.46 mm² / 2.24 mm²; 192 KB SRAM; 50–200 MHz; 0.56–1.1 V; power 2.84–43.58 mW; peak performance 230.4 GOPS; best dense energy efficiency 20.28 TOPS/W without sparsity | BF6: Yes. Compares against sparse ANN processors and discusses ANN MAC baseline versus SNN AC-only processing | BG6: Contribution: proposes a fabricated 40-nm sparse DSNN accelerator that supports modern direct-trained Spiking Transformers and Spiking ResNets using timestep-parallel computation, non-zero spike fetching, and operator-specific scheduling. Limitation: focuses mainly on vision/image and DVS benchmarks; training details are not reported; first non-spiking convolution/preprocessing for DVS is implemented on FPGA rather than fully on-chip | BH6: Primary: RQ5; Secondary: RQ2, RQ3
A7: P006 | B7: Gao, Y., Wang, T., Yang, Y., Gong, L., Chen, X., Wang, C., Li, X., & Zhou, X. (2025). Advancing Neuromorphic Architecture Toward Emerging Spiking Neural Network on FPGA. IEEE Transactions on Computer-Aided Design of Integrated Circuits and Systems, 44(9), 3465–3478. https://doi.org/10.1109/TCAD.2025.3547275 | C7: Advancing Neuromorphic Architecture Toward Emerging Spiking Neural Network on FPGA | D7: University of Science and Technology of China | E7: China | F7: 2025 | G7: IEEE Transactions on Computer-Aided Design of Integrated Circuits and Systems | H7: IEEE | I7: https://doi.org/10.1109/TCAD.2025.3547275 | J7: Journal article | K7: IEEE Xplore | L7: Hardware-focused | M7: 4.5 | N7: Neuromorphic Hardware and Edge AI Acceleration | O7: Accelerating Transformer Spiking Neural Network inference on FPGA for CIFAR-10, CIFAR-100, and ImageNet classification | P7: Static image data converted into spike sequences | Q7: 2D image sequence represented as X ∈ R(T×C×H×W), then reshaped into spike patches I ∈ R(T×N×D) | R7: Input spikes are represented by 1-bit values; synapse weights are quantized to 8-bit; TSNN uses spike patches, channel dimension, timesteps, and LIF neuron dynamics | S7: CIFAR-10, CIFAR-100, ImageNet | T7: Public image classification benchmark datasets | U7: NR | V7: NR | W7: Transformer Spiking Neural Network accelerated by heterogeneous FPGA architecture; TSNN consists of spiking patch splitting, L-block spike encoder, spike-driven self-attention module, spike MLP module, shortcut connections, and classification head | X7: LIF spike neuron layers, binary spikes, spiking patch splitting, spike encoder, spike-driven self-attention, spike MLP, membrane shortcut | Y7: LIF | Z7: Transformer Spiking Neural Network; spike-driven self-attention; spike MLP; spike encoder blocks | AA7: Spike-driven self-attention using mask and accumulation operations | AB7: Spike neuron layers convert inputs into binary spike vectors; spike linear transformation generates Qs, Ks, and Vs; SDSA applies mask operations between Ks and Vs, accumulates along spike patches, then masks with Qs | AC7: CIFAR-10: 10.23M parameters, 9.88G mult-add, spike patches 64, channel 512, 2 blocks, 4 timesteps; CIFAR-100: 10.28M parameters, 9.88G mult-add, spike patches 64, channel 512, 2 blocks, 4 timesteps; ImageNet: 29.69M parameters, 66.09G mult-add, spike patches 196, channel 512, 8 blocks, 4 timesteps | AD7: CIFAR-10: 10.23M; CIFAR-100: 10.28M; ImageNet: 29.69M | AE7: FPGA-based neuromorphic architecture named SpikeTA; heterogeneous hardware engines; DSP-efficient addition tree; depth-aware buffer management; streaming dataflow mapping; split-engine dataflow mapping; latency-aware parallelism search | AF7: Spiking patch splitting converts image sequences into spike patch sequences; LIF spike neuron layers convert continuous inputs into spike sequences | AG7: 1-bit input spikes; 8-bit synapse weights; membrane threshold = 1.0; coefficient τ = 2.0; timestep = 4 for evaluated TSNN models | AH7: Partially learned: TSNN is trained/fine-tuned using backpropagation; hardware mapping/dataflow and quantization are fixed deployment mechanisms | AI7: Binary spike vectors; spike patches; Qs/Ks/Vs spike matrices; 1-bit spike inputs with 8-bit synaptic weights | AJ7: 4 timesteps | AK7: Classification head performs final image classification | AL7: Partial. The paper analyzes spike representation, LIF charging/firing/resetting, spike-driven MAAC computation, and hardware buffering/dataflow for timesteps, but does not deeply analyze temporal information preservation | AM7: Supervised direct training / fine-tuning of TSNN | AN7: Backpropagation training with surrogate function; quantization optimization within 10 epochs using the training recipe from Spike-driven Transformer | AO7: Sigmoid surrogate function | AP7: N/A | AQ7: NR | AR7: NR | AS7: PyTorch 2.3.1, CuPy 13.2, SpikingJelly 0.0.0.0.10, CUDA 12.4; quantization optimization within 10 epochs; training time about 11 min for CIFAR-10, 23 min for CIFAR-100, and 2 days for ImageNet on NVIDIA A100; threshold 1.0; τ = 2.0; 1-bit spikes; 8-bit weights | AT7: Architecture performance, speedup, energy efficiency, classification accuracy | AU7: Peak performance: 28.99 TOPs; end-to-end execution time: 1.11 s for CIFAR-10, 1.11 s for CIFAR-100, and 68.08 s for ImageNet; accuracy: 95.60% on CIFAR-10, 78.40% on CIFAR-100, and 74.56% on ImageNet | AV7: GOPs/W, power consumption, hardware utilization, FPGA resource utilization, DSP/LUT/BRAM/URAM usage, execution latency, performance speedup over CPU/GPU/accelerators | AW7: AMD EPYC 7542 CPU; NVIDIA A100 GPU; FireFly; DeepFire2; E3NE; HeatViT; SSR Transformer accelerator; other SNN and non-spiking Transformer accelerators | AX7: 140.73×–1023.53× speedup over AMD EPYC 7542 CPU; 2.97×–7.29× speedup over NVIDIA A100 GPU; 223.21×–2150.18× energy-efficiency gain over CPU; 6.41×–28.04× energy-efficiency gain over GPU; 2.79× over SOTA SNN accelerator; 2.66× over SOTA non-spiking Transformer accelerator | AY7: Benchmark and hardware comparison across three datasets; no standard deviation, confidence interval, repeated-run analysis, or statistical significance test reported | AZ7: Partial hardware ablation. Includes comparison of computing strategies SpikeTA-op1/op2/op3/final, hardware utilization analysis, resource utilization breakdown, and pipelined latency balancing analysis | BA7: PyTorch, CuPy, SpikingJelly, CUDA 12.4 for training; Xilinx Vitis HLS/Vivado for FPGA implementation; code availability NR | BB7: Xilinx Alveo U280 FPGA with xcu280-fsvh2892-2L-e chip; 9024 DSPs, 1304k LUTs, 2607k FFs, 2016 BRAMs, 960 URAMs, and 32 HBM channels | BC7: Implemented and evaluated on FPGA prototype using Vitis HLS and Vivado | BD7: Power measured using Xilinx Board Utility xbutil; reported power consumption is 70.93 W, 71.45 W, and 71.76 W on CIFAR-10, CIFAR-100, and ImageNet respectively; energy efficiency reported up to 403.99 GOPs/W | BE7: Clock frequency 450 MHz; uses three parallel hardware kernels across SLRs; end-to-end times of 1.11 s, 1.11 s, and 68.08 s; total hardware utilization about 91.87%–91.94%; resource use includes 61.87% URAM, 77.98% BRAM, 79.43% DSP, 8.87% LUTRAM, and 63.86% LUTCOM | BF7: Yes. Compares with non-spiking Transformer accelerators and CPU/GPU ANN-style execution baselines | BG7: Contribution: proposes SpikeTA, the first FPGA-based neuromorphic hardware architecture explicitly designed for TSNN acceleration, using heterogeneous hardware engines, DSP-efficient addition, depth-aware buffering, and optimized dataflow mapping. Limitation: evaluated only on image classification TSNN models; energy efficiency is FPGA-board based rather than ASIC silicon; adaptability to broader TSNN models is left for future work | BH7: Primary: RQ5; Secondary: RQ2, RQ3, RQ4
A8: P007 | B8: Guo, Y., Liu, X., Chen, Y., Peng, W., Zhang, Y., & Ma, Z. (2025). Spiking Transformer: Introducing Accurate Addition-Only Spiking Self-Attention for Transformer. In Proceedings of the IEEE/CVF Conference on Computer Vision and Pattern Recognition (CVPR 2025), pp. 24398–24408. https://doi.org/10.1109/CVPR52734.2025.02272 | C8: Spiking Transformer: Introducing Accurate Addition-Only Spiking Self-Attention for Transformer | D8: Peking University | E8: China | F8: 2025 | G8: IEEE/CVF Conference on Computer Vision and Pattern Recognition, CVPR 2025 | H8: IEEE | I8: https://doi.org/10.1109/CVPR52734.2025.02272 | J8: Conference paper | K8: IEEE Xplore | L8: Application-focused | M8: 4.5 | N8: Computer Vision and Image Understanding | O8: Image classification on CIFAR-10, CIFAR-100, and ImageNet-1K | P8: Static RGB image data represented as repeated image sequences over timesteps | Q8: 2D images converted into spiking patch sequences, I ∈ R(T×C×H×W), then represented as N flattened spike patches with D-dimensional channels | R8: CIFAR images are 32 × 32; ImageNet-1K images are resized to 224 × 224; images are repeated across T timesteps; main experiments use 4 timesteps | S8: CIFAR-10, CIFAR-100, ImageNet-1K | T8: Public image classification benchmark datasets | U8: CIFAR: 50,000 training images and 10,000 test images; ImageNet-1K: approximately 1.28 million training images and 50,000 test images | V8: Uses standard train/test benchmark splits; exact class-balance details NR | W8: Spiking Transformer with Spiking Patch Splitting, L-block Spiking Transformer encoder, Accurate Addition-Only Spiking Self-Attention, MLP block, membrane-potential residual connections, global average pooling, and classification head | X8: LIF spike neuron layers, binary spiking neuron for Q, ternary spiking neuron for V, binary spike hidden states, membrane potential dynamics, spike-based residual structure | Y8: LIF; binary spiking neuron; ternary spiking neuron | Z8: Spiking Transformer encoder block, A2OS2A attention module, MLP block, patch-splitting module, relative position embedding, classification head | AA8: Accurate Addition-Only Spiking Self-Attention; binary Q, ReLU/full-precision K, ternary V; softmax-free and scaling-free attention | AB8: Linear + BN layers generate Q, K, and V; Q is converted by binary spiking neuron, K by ReLU, and V by ternary spiking neuron; Q·Kᵀ·V is computed through addition-only operations instead of conventional multiplication-heavy self-attention | AC8: Reported models include Spiking Transformer-2-256, 2-384, 4-256, 4-384, 2-512, 8-384, 6-512, 8-512, and 10-512; main ImageNet models use 4 timesteps | AD8: CIFAR models: 2.59M, 4.15M, 5.76M, 9.32M, and 10.23M depending on model scale; ImageNet models: 16.81M, 23.37M, 29.68M, and 36.01M | AE8: New spiking self-attention mechanism, A2OS2A, designed to reduce information loss while preserving addition-only computation; theoretical analysis of information loss in vanilla spiking self-attention | AF8: Spiking Patch Splitting converts repeated image sequence into spike patch embeddings; spike neuron layer converts membrane potentials into spike tensors | AG8: Main experiments use T = 4 timesteps; binary Q values {0,1}; ternary V values {-1,0,1}; ReLU/full-precision K; LIF threshold Vth, reset potential Vreset, and decay factor β are defined but exact values NR | AH8: Partially learned: patch projection, Q/K/V projections, BN, RPE, and model weights are learned; spike firing rules are fixed neuron dynamics | AI8: Binary spike tensors; binary Q; ternary V; spike patch embeddings; membrane potential tensors; binary hidden states | AJ8: 4 timesteps in the main reported experiments | AK8: Global Average Pooling over final Spiking Transformer encoder output followed by a fully connected classification head | AL8: Yes. The paper provides entropy-based theoretical analysis of information loss in binary spike representations and compares representational capacity of binary spike features versus real-valued features | AM8: Supervised direct learning | AN8: Direct training of Spiking Transformer following Spike-driven Transformer experimental setup; backpropagation with surrogate-gradient-style training implied through LIF neuron discussion | AO8: NR | AP8: N/A | AQ8: NR | AR8: NR | AS8: Main experiments use 4 timesteps; other training configurations follow Spike-driven Transformer; detailed optimizer, learning rate, batch size, and schedule NR | AT8: Top-1 classification accuracy | AU8: Best reported accuracy: 96.42% on CIFAR-10, 79.90% on CIFAR-100, and 78.66% on ImageNet-1K | AV8: Parameter count, timestep count, ablation accuracy gain over baseline | AW8: Hybrid training, Diet-SNN, STBP, STBP-NeuNorm, TSSL-BP, STBP-tdBN, TET, Spikformer, Spikingformer, Spike-driven Transformer, Spiking ResNet, QCFS, COS, SEW-ResNet, Attention-SNN | AX8: CIFAR-10/100: Spiking Transformer-2-512 improves over baseline by about 0.91% on CIFAR-10 and 1.07% on CIFAR-100. ImageNet: Spiking Transformer-8-512 reaches 76.28%, improving over Spikingformer-8-512 by 1.49%; Spiking Transformer-10-512 reaches 78.66% | AY8: Benchmark comparison and ablation study; no standard deviation, confidence interval, repeated-run analysis, or statistical significance test reported | AZ8: Full/clear ablation. Compares baseline Spike-driven Transformer variants against the proposed Spiking Transformer on CIFAR-10 and CIFAR-100 for 2-256 and 2-512 models | BA8: Training framework NR; code availability NR | BB8: Neuromorphic hardware motivation discussed; no specific hardware deployment target used in experiments | BC8: No hardware deployment reported | BD8: No measured energy result; efficiency is argued theoretically through addition-only computation, removal of softmax/scaling, and SNN event-driven properties | BE8: Reports parameter counts and timesteps; no measured latency, memory footprint, or computational complexity table reported | BF8: Partial. Compares against ANN-to-SNN methods and SNN baselines; does not directly evaluate a matched ANN Transformer baseline in experiments | BG8: Contribution: proposes A2OS2A, a more accurate addition-only spiking self-attention mechanism using binary Q, ReLU K, and ternary V to reduce information loss while avoiding softmax and scaling. Limitation: no hardware implementation or measured energy/latency results; several training details are not reported and are referred to prior baseline settings | BH8: Primary: RQ2; Secondary: RQ3, RQ4, RQ1
A9: P008 | B9: Jung, H., Lee, K., & Park, J. (2026). A Structured-Sparsity-Based Design Approach for Energy-Efficient Spiking Transformer Processing. IEEE Transactions on Very Large Scale Integration (VLSI) Systems. https://doi.org/10.1109/TVLSI.2026.3675299 | C9: A Structured-Sparsity-Based Design Approach for Energy-Efficient Spiking Transformer Processing | D9: Korea University | E9: South Korea | F9: 2026 | G9: IEEE Transactions on Very Large Scale Integration (VLSI) Systems | H9: IEEE | I9: https://doi.org/10.1109/TVLSI.2026.3675299 | J9: Journal article | K9: IEEE Xplore | L9: Hardware-focused | M9: 4.5 | N9: Neuromorphic Hardware and Edge AI Acceleration | O9: Structured-sparsity-based acceleration of Spiking Transformer SSA blocks for image classification, object detection, and semantic segmentation | P9: Static image data represented through spike activations in Spiking Transformer models | Q9: Spiking token tensors with timestep, token, and channel dimensions; SSA inputs represented as X ∈ {0,1}^(T×N×Cin), with Q/K/V split into attention heads | R9: Binary spike activations; sparse SSA intermediate matrix A and output matrix Z; rowwise sparsity in A and columnwise sparsity in Z; low-spike-rate neurons firing at most once across timesteps are filtered during sparsity detection | S9: ImageNet-1K, CIFAR-10, CIFAR-100, COCO 2017, ADE20K | T9: Public image classification, object detection, and semantic segmentation benchmark datasets | U9: NR | V9: NR | W9: Spiking Transformer SSA block with QKV generation, SSA/FSSA mechanism, and projection layer; proposed fully spiking SSA inserts additional LIF neuron after KᵀV to increase structured sparsity | X9: LIF neurons, spike activations, FSSA operator, low-spike-rate neuron filtering, sparse spike tensors, structured sparsity detection | Y9: LIF neuron with learnable threshold voltage | Z9: Spiking self-attention block; QKV generation layer; attention heads; projection layer; Spikingformer, Spike-driven Transformer v2, and QKFormer models | AA9: Spiking self-attention; fully spiking SSA; structured-sparsity-aware SSA | AB9: Q, K, and V are generated as spike tensors using spiking neuron layers; FSSA adds LIF neuron to transform intermediate KᵀV attention matrix into sparse spike activation before Q·A computation | AC9: Evaluated ST models include Spikingformer, Spike-driven Transformer v2, QKFormer-224, and QKFormer-384; exact block counts and parameter counts for each model NR in this paper | AD9: Object detection SDT v2: 34.9M; ADE20K semantic segmentation SDT v2: 16.5M; classification model parameter counts NR | AE9: Algorithm–hardware co-design introducing FSSA, low-spike-rate neuron filtering, sparsity-aware two-stage dataflow, and sparsity-aware hardware add-on for runtime computation and memory-transfer skipping | AF9: Uses pretrained Spiking Transformer models with binary spike activations; exact image-to-spike input encoding method NR | AG9: FSSA LIF threshold initialized to vth = 4; neuron filtering treats neurons firing at most once over all timesteps as sparse; fine-tuning for 10 epochs | AH9: Partially learned: FSSA LIF thresholds are learnable and QKV generation weights are fine-tuned; sparsity detection/filtering logic is fixed | AI9: Binary spike activations; spike tensors Q, K, V; sparse A and Z matrices; compact binary sparsity vectors for active/inactive channels | AJ9: T timesteps used in evaluated ST models; exact timestep varies by model/task and is not fully reported; COCO uses timestep 1, ADE20K uses timestep 4 | AK9: Classification head / downstream task heads from the underlying ST models; exact decoding details NR | AL9: Yes. The paper analyzes SSA structured sparsity, rowwise sparsity in A, columnwise sparsity in Z, low-spike-rate neurons across timesteps, and sparsity effects on computation and memory skipping | AM9: Supervised fine-tuning of pretrained Spiking Transformer models | AN9: Lightweight fine-tuning restricted mainly to QKV generation layers and learnable FSSA LIF thresholds; 10 epochs of fine-tuning | AO9: NR | AP9: N/A | AQ9: NR | AR9: NR | AS9: FSSA threshold initialized to 4; fine-tuned for 10 epochs; QKV generation weights updated; up to 80% fewer fine-tuned parameters than full-model fine-tuning; other optimizer and learning-rate details NR | AT9: Effective throughput and energy efficiency of SSA block processing | AU9: Proposed design with filtering achieves 234.44 GOP/s effective throughput and 319.12 GOP/J energy efficiency | AV9: Accuracy, structured sparsity, row-A sparsity, column-Z sparsity, area overhead, power overhead, mAP, mIoU | AW9: Baseline SSA/ST models; Spikingformer, Spike-driven Transformer v2, QKFormer; baseline SNN accelerator/Prosperity; PTB; Bishop; SpikeX; Phi | AX9: FSSA increases structured sparsity by about 1.8× with less than 1% accuracy loss; neuron filtering adds about 1.5× more sparsity over FSSA; proposed hardware achieves 24.3% throughput gain and 28.2% energy-efficiency gain over baseline SNN accelerator | AY9: Benchmark evaluation and postsynthesis simulation; no standard deviation, confidence interval, repeated-run analysis, or statistical significance test reported | AZ9: Full. Includes FSSA direct implementation, FSSA suppression-method comparison, FSSA fine-tuning, neuron-filtering fine-tuning, downstream detection/segmentation evaluation, hardware overhead, and accelerator comparison | BA9: Hardware implemented in Verilog RTL; synthesized with Synopsys Design Compiler in 28 nm process; evaluated using open-source cycle-accurate simulator for Prosperity; training framework/code availability NR | BB9: 28 nm SNN accelerator-style hardware integrated with sparsity-aware hardware modules; baseline modeled using Prosperity accelerator framework | BC9: RTL synthesis and cycle-accurate simulation; no fabricated chip reported | BD9: Energy estimated from postsynthesis simulation and synthesized hardware power; proposed sparsity-aware hardware consumes 2.23 mW with 0.24% power overhead over baseline | BE9: Proposed sparsity-aware hardware area 0.0057 mm²; 1.08% area overhead; 500 MHz frequency; 128 processing elements; skips redundant computations and weight transfers in Q generation and projection layers | BF9: Partial. Motivation compares ST accuracy/efficiency with ANN transformers, but experiments mainly compare against SNN/ST models and SNN accelerators rather than a matched ANN baseline | BG9: Contribution: identifies and exploits structured sparsity in SSA through FSSA, low-spike-rate neuron filtering, and sparsity-aware hardware/dataflow to improve ST throughput and energy efficiency. Limitation: hardware results are based on RTL synthesis and simulation rather than fabricated silicon; optimization focuses mainly on SSA blocks rather than full end-to-end accelerator deployment | BH9: Primary: RQ5; Secondary: RQ2, RQ3, RQ4
